Workbook

Sheet Assumptions
A1: Pricing Assumptions
A3: Competitive positioning
A4: Commodity undercut vs competitor | B4: 0.97
A5: Branded premium vs competitor | B5: 1.05
A7: Quantity tier factors
A8: Tier | B8: Max Pack Qty | C8: Factor
A9: Small | B9: 100 | C9: 1.05
A10: Medium | B10: 500 | C10: 1
A11: Large | B11: 2000 | C11: 0.95
A12: XL | B12: 999999 | C12: 0.9
A14: Margin targets
A15: CategoryGroup | B15: Target Margin | C15: Min Margin
A16: Packaging | B16: 0.35 | C16: 0.25
A17: Bags | B17: 0.35 | C17: 0.25
A18: Branded | B18: 0.55 | C18: 0.4
A19: Custom | B19: 0.6 | C19: 0.45
A20: Other | B20: 0.4 | C20: 0.3

Sheet Competitor Benchmarks
A1: Competitor Benchmarks (sources in URL column)
A2: Key | B2: Competitor | C2: Pack Price | D2: Pack Qty | E2: Unit Price | F2: URL | G2: Notes
A3: Bags|3x4.5 | B3: Dragon Chewer (1 gram, 1000 qty listing) | C3: 59.95 | D3: 1000 | E3: 0.05995 | F3: https://dragonchewer.com/collections/1000-qty-mylar-bags | G3: Listing shows 1 Gram Gloss Black & Clear Mylar Bags (1000 qty) as low as $59.95/case ($0.05/unit).
A4: Bags|3.6x5 | B4: Dragon Chewer (1/8 oz black/clear, 1000 qty) | C4: 79.95 | D4: 1000 | E4: 0.07995 | F4: https://dragonchewer.com/products/1-8-ounce-gloss-black-clear-mylar-bags-1000-qty | G4: Product page shows sale price $79.95 for 1000 qty (3.62x5 style).
A5: Bags|4x6.5 | B5: Dragon Chewer (1/4 oz, 1000 qty listing) | C5: 79.95 | D5: 1000 | E5: 0.07995 | F5: https://dragonchewer.com/collections/1000-qty-mylar-bags | G5: Listing shows 1/4 Ounce Matte Black & Clear Mylar Bags (1000 qty) as low as $79.95/case ($0.07/unit).
A6: Bags|5x8 | B6: Dragon Chewer (1/2 oz, 1000 qty listing) | C6: 109.95 | D6: 1000 | E6: 0.10995 | F6: https://dragonchewer.com/collections/1000-qty-mylar-bags | G6: Listing shows 1/2 Ounce Gloss Black & Clear Mylar Bags (1000 qty) as low as $109.95/case ($0.10/unit).
A7: Bags|6x9 | B7: Dragon Chewer (1 oz, 1000 qty listing) | C7: 129.95 | D7: 1000 | E7: 0.12995 | F7: https://dragonchewer.com/collections/1000-qty-mylar-bags | G7: Listing shows 1 Ounce Gloss Black & Clear Mylar Bags (1000 qty) as low as $129.95/case ($0.12/unit).
A8: Bags|9x2.5 | B8: Dragon Chewer (2.5x9 syringe bag, 1000 qty) | C8: 79.95 | D8: 1000 | E8: 0.07995 | F8: https://dragonchewer.com/products/2-5-x-9-inch-matte-black-syringe-mylar-bags-1000-qty | G8: Product page shows sale price $79.95 for 1000 qty (2.5x9).
A9: Bags|4x6.5|low | B9: Marijuana Packaging (clearance sale) | C9: 44.81 | D9: 1000 | E9: 0.04481 | F9: https://marijuanapackaging.com/collections/mylar-bags/products/glossy-black-4-x-6-5-vista-mylar-tamper-evident-bags-7-grams-1000-box | G9: Sale price observed on product page; may be clearance / promotional.
A10: Tubes|116mm | B10: Biohazard Inc (1000 count) | C10: 69 | D10: 1000 | E10: 0.069 | F10: https://www.biohazardinc.com/products/pre-roll-child-resistant-opaque-tubes-hinged-lid | G10: 116mm black tubes, 1000ct listed at $69.00; page shows tiered pricing for larger case quantities.
A11: Tubes|116mm|small | B11: Bag King (packs of 100) | C11: 12 | D11: 100 | E11: 0.12 | F11: https://www.bagking.com/products/pre-roll-tubes | G11: Bag King indicates $0.12 each and sold in packs of 100 (case quantity 1000).
A12: Jars|7ml | B12: SODO LOCO (90 pack) | C12: 43 | D12: 90 | E12: 0.47777778 | F12: https://sodoloco.com/products/low-profile-7ml-glass-jars-child-resistant-black-lid-90 | G12: Low profile 7ml glass jar with black lid; 90 pack listed at $43.
A13: Jars|5ml | B13: True Aroma (320 pack) | C13: 271.99 | D13: 320 | E13: 0.84996875 | F13: https://truearoma.com/products/5ml-thick-clear-glass-containers-with-black-child-resistant-lids | G13: 5ml thick clear glass containers with black child resistant lids; 320 pack listed at $271.99.
A14: Jars|3oz | B14: Dragon Chewer (150 qty) | C14: 69.95 | D14: 150 | E14: 0.46633333 | F14: https://dragonchewer.com/products/3-ounce-clear-glass-jar-child-resistant-white-smooth-cap-150-qty-1 | G14: 3 ounce glass jar with child resistant cap; 150 qty sale price $69.95.
... A18: FEP|Roll | B18: Kraft & Kitchen (FEP bulk roll) | C18: 210 | D18: 50 | E18: 4.2 | F18: https://kraftandkitchen.com/products/kraft-kitchen-sheet-ptfe-rolls | G18: Related items on PTFE roll page show "Bulk Roll of FEP film... from $210.00" (length not shown in static HTML; assumed 50ft to align with common 50ft rolls).

Sheet SKU Master
A1: Master SKU List with Competitor Benchmarks + Recommended Pricing
A2: Handle | B2: Product Title | C2: Short Description | D2: Variant Options | E2: SKU | F2: CategoryGroup | G2: Pack Qty | H2: Unit Type | I2: Current Pack Price | J2: Current Pack COGS | K2: Current Unit Price | L2: Current Unit Cost | M2: Current Margin % | N2: Competitor Ref Pack Price | O2: Competitor Ref Pack Qty | P2: Competitor Ref Unit Price | Q2: Competitor Low Pack Price | R2: Competitor Low Pack Qty | S2: Competitor Low Unit Price | T2: Benchmark Type | U2: Competitor Source URL | V2: Benchmark Notes | W2: Tier Factor | X2: Position Factor | Y2: Target Margin | Z2: Min Margin | AA2: Base Rec Unit Price | AB2: Min Unit Price (Margin) | AC2: Recommended Unit Price | AD2: Recommended Pack Price | AE2: Recommended Shopify Price | AF2: Pricing Notes
A3: 6ml-glass-no-neck-jar | B3: 6ml Glass No-Neck Jar with Silicone lid | C3: The 6ml Glass No‑Neck Jar with Silicone Lid is a straight-sided glass concentrate jar built for extractors, processors, and brands who hate leaving material behind. The no‑neck design makes every scrape clean and efficie… | D3: Quantity: 200 | E3: NONECK1 | F3: Packaging | G3: 200 | H3: pcs | I3: 39.99 | K3: =IFERROR(I3/G3,"") | L3: =IFERROR(J3/G3,"") | M3: =IFERROR((I3-J3)/I3,"") | P3: =IFERROR(N3/O3,"") | S3: =IFERROR(Q3/R3,"") | W3: =IF(G3="","",IF(G3<=Assumptions!$B$9,Assumptions!$C$9,IF(G3<=Assumptions!$B$10,Assumptions!$C$10,IF(G3<=Assumptions!$B$11,Assumptions!$C$11,Assumptions!$C$12)))) | X3: =IF(F3="Branded",Assumptions!$B$5,IF(OR(F3="Packaging",F3="Bags"),Assumptions!$B$4,1)) | Y3: =IFERROR(VLOOKUP(F3,Assumptions!$A$16:$C$20,2,FALSE),0.40) | Z3: =IFERROR(VLOOKUP(F3,Assumptions!$A$16:$C$20,3,FALSE),0.30) | AA3: =IF(P3<>"",P3*X3*W3,IF(L3<>"",L3/(1-Y3),K3)) | AB3: =IF(L3<>"",L3/(1-Z3),"") | AC3: =IF(AB3="",AA3,MAX(AA3,AB3)) | AD3: =IF(AC3="","",AC3*G3) | AE3: =IF(AD3="","",ROUNDUP(AD3,0)-0.01) | AF3: =IF(P3<>"","Competitor-based",IF(L3<>"","Cost+margin","Needs review"))
A4: 6ml-glass-no-neck-jar | B4: 6ml Glass No-Neck Jar with Silicone lid | C4: The 6ml Glass No‑Neck Jar with Silicone Lid is a straight-sided glass concentrate jar built for extractors, processors, and brands who hate leaving material behind. The no‑neck design makes every scrape clean and efficie… | D4: Quantity: 400 | E4: NONECK2 | F4: Packaging | G4: 400 | H4: pcs | I4: 42.99 | K4: =IFERROR(I4/G4,"") | L4: =IFERROR(J4/G4,"") | M4: =IFERROR((I4-J4)/I4,"") | P4: =IFERROR(N4/O4,"") | S4: =IFERROR(Q4/R4,"") | W4: =IF(G4="","",IF(G4<=Assumptions!$B$9,Assumptions!$C$9,IF(G4<=Assumptions!$B$10,Assumptions!$C$10,IF(G4<=Assumptions!$B$11,Assumptions!$C$11,Assumptions!$C$12)))) | X4: =IF(F4="Branded",Assumptions!$B$5,IF(OR(F4="Packaging",F4="Bags"),Assumptions!$B$4,1)) | Y4: =IFERROR(VLOOKUP(F4,Assumptions!$A$16:$C$20,2,FALSE),0.40) | Z4: =IFERROR(VLOOKUP(F4,Assumptions!$A$16:$C$20,3,FALSE),0.30) | AA4: =IF(P4<>"",P4*X4*W4,IF(L4<>"",L4/(1-Y4),K4)) | AB4: =IF(L4<>"",L4/(1-Z4),"") | AC4: =IF(AB4="",AA4,MAX(AA4,AB4)) | AD4: =IF(AC4="","",AC4*G4) | AE4: =IF(AD4="","",ROUNDUP(AD4,0)-0.01) | AF4: =IF(P4<>"","Competitor-based",IF(L4<>"","Cost+margin","Needs review"))
A5: 6ml-glass-no-neck-jar | B5: 6ml Glass No-Neck Jar with Silicone lid | C5: The 6ml Glass No‑Neck Jar with Silicone Lid is a straight-sided glass concentrate jar built for extractors, processors, and brands who hate leaving material behind. The no‑neck design makes every scrape clean and efficie… | D5: Quantity: 1000 | E5: NONECK3 | F5: Packaging | G5: 1000 | H5: pcs | I5: 49.99 | K5: =IFERROR(I5/G5,"") | L5: =IFERROR(J5/G5,"") | M5: =IFERROR((I5-J5)/I5,"") | P5: =IFERROR(N5/O5,"") | S5: =IFERROR(Q5/R5,"") | W5: =IF(G5="","",IF(G5<=Assumptions!$B$9,Assumptions!$C$9,IF(G5<=Assumptions!$B$10,Assumptions!$C$10,IF(G5<=Assumptions!$B$11,Assumptions!$C$11,Assumptions!$C$12)))) | X5: =IF(F5="Branded",Assumptions!$B$5,IF(OR(F5="Packaging",F5="Bags"),Assumptions!$B$4,1)) | Y5: =IFERROR(VLOOKUP(F5,Assumptions!$A$16:$C$20,2,FALSE),0.40) | Z5: =IFERROR(VLOOKUP(F5,Assumptions!$A$16:$C$20,3,FALSE),0.30) | AA5: =IF(P5<>"",P5*X5*W5,IF(L5<>"",L5/(1-Y5),K5)) | AB5: =IF(L5<>"",L5/(1-Z5),"") | AC5: =IF(AB5="",AA5,MAX(AA5,AB5)) | AD5: =IF(AC5="","",AC5*G5) | AE5: =IF(AD5="","",ROUNDUP(AD5,0)-0.01) | AF5: =IF(P5<>"","Competitor-based",IF(L5<>"","Cost+margin","Needs review"))
A6: 7ml-screw-top-jars-with-black-lids | B6: 7ml Glass Jars- Low Profile heavy bottom- Screw Top with Lids | C6: The 7ml Low Profile Heavy Bottom Glass Jar is a lab-grade concentrate container built for extractors, processors, and brands who need packaging that performs on the bench and looks right on the shelf. At 7ml (0.24 fl oz)… | D6: Quantity: 90 / Lid Color: Black / Glass: Clear | E6: 7MLJAR-01B | F6: Packaging | G6: 90 | H6: pcs | I6: 49.99 | K6: =IFERROR(I6/G6,"") | L6: =IFERROR(J6/G6,"") | M6: =IFERROR((I6-J6)/I6,"") | N6: 43 | O6: 90 | P6: =IFERROR(N6/O6,"") | S6: =IFERROR(Q6/R6,"") | T6: Observed | U6: https://sodoloco.com/products/low-profile-7ml-glass-jars-child-resistant-black-lid-90 | V6: Low profile 7ml glass jar with black lid; 90 pack listed at $43. | W6: =IF(G6="","",IF(G6<=Assumptions!$B$9,Assumptions!$C$9,IF(G6<=Assumptions!$B$10,Assumptions!$C$10,IF(G6<=Assumptions!$B$11,Assumptions!$C$11,Assumptions!$C$12)))) | X6: =IF(F6="Branded",Assumptions!$B$5,IF(OR(F6="Packaging",F6="Bags"),Assumptions!$B$4,1)) | Y6: =IFERROR(VLOOKUP(F6,Assumptions!$A$16:$C$20,2,FALSE),0.40) | Z6: =IFERROR(VLOOKUP(F6,Assumptions!$A$16:$C$20,3,FALSE),0.30) | AA6: =IF(P6<>"",P6*X6*W6,IF(L6<>"",L6/(1-Y6),K6)) | AB6: =IF(L6<>"",L6/(1-Z6),"") | AC6: =IF(AB6="",AA6,MAX(AA6,AB6)) | AD6: =IF(AC6="","",AC6*G6) | AE6: =IF(AD6="","",ROUNDUP(AD6,0)-0.01) | AF6: =IF(P6<>"","Competitor-based",IF(L6<>"","Cost+margin","Needs review"))
A7: 7ml-screw-top-jars-with-black-lids | B7: 7ml Glass Jars- Low Profile heavy bottom- Screw Top with Lids | C7: The 7ml Low Profile Heavy Bottom Glass Jar is a lab-grade concentrate container built for extractors, processors, and brands who need packaging that performs on the bench and looks right on the shelf. At 7ml (0.24 fl oz)… | D7: Quantity: 90 / Lid Color: Black / Glass: Frosted | E7: 7MLJAR-01BF | F7: Packaging | G7: 90 | H7: pcs | I7: 9.99 | K7: =IFERROR(I7/G7,"") | L7: =IFERROR(J7/G7,"") | M7: =IFERROR((I7-J7)/I7,"") | N7: 43 | O7: 90 | P7: =IFERROR(N7/O7,"") | S7: =IFERROR(Q7/R7,"") | T7: Observed | U7: https://sodoloco.com/products/low-profile-7ml-glass-jars-child-resistant-black-lid-90 | V7: Low profile 7ml glass jar with black lid; 90 pack listed at $43. | W7: =IF(G7="","",IF(G7<=Assumptions!$B$9,Assumptions!$C$9,IF(G7<=Assumptions!$B$10,Assumptions!$C$10,IF(G7<=Assumptions!$B$11,Assumptions!$C$11,Assumptions!$C$12)))) | X7: =IF(F7="Branded",Assumptions!$B$5,IF(OR(F7="Packaging",F7="Bags"),Assumptions!$B$4,1)) | Y7: =IFERROR(VLOOKUP(F7,Assumptions!$A$16:$C$20,2,FALSE),0.40) | Z7: =IFERROR(VLOOKUP(F7,Assumptions!$A$16:$C$20,3,FALSE),0.30) | AA7: =IF(P7<>"",P7*X7*W7,IF(L7<>"",L7/(1-Y7),K7)) | AB7: =IF(L7<>"",L7/(1-Z7),"") | AC7: =IF(AB7="",AA7,MAX(AA7,AB7)) | AD7: =IF(AC7="","",AC7*G7) | AE7: =IF(AD7="","",ROUNDUP(AD7,0)-0.01) | AF7: =IF(P7<>"","Competitor-based",IF(L7<>"","Cost+margin","Needs review"))
A8: 7ml-screw-top-jars-with-black-lids | B8: 7ml Glass Jars- Low Profile heavy bottom- Screw Top with Lids | C8: The 7ml Low Profile Heavy Bottom Glass Jar is a lab-grade concentrate container built for extractors, processors, and brands who need packaging that performs on the bench and looks right on the shelf. At 7ml (0.24 fl oz)… | D8: Quantity: 180 / Lid Color: Black / Glass: Clear | E8: 7MLJAR-02B | F8: Packaging | G8: 180 | H8: pcs | I8: 12.99 | K8: =IFERROR(I8/G8,"") | L8: =IFERROR(J8/G8,"") | M8: =IFERROR((I8-J8)/I8,"") | N8: 43 | O8: 90 | P8: =IFERROR(N8/O8,"") | S8: =IFERROR(Q8/R8,"") | T8: Observed | U8: https://sodoloco.com/products/low-profile-7ml-glass-jars-child-resistant-black-lid-90 | V8: Low profile 7ml glass jar with black lid; 90 pack listed at $43. | W8: =IF(G8="","",IF(G8<=Assumptions!$B$9,Assumptions!$C$9,IF(G8<=Assumptions!$B$10,Assumptions!$C$10,IF(G8<=Assumptions!$B$11,Assumptions!$C$11,Assumptions!$C$12)))) | X8: =IF(F8="Branded",Assumptions!$B$5,IF(OR(F8="Packaging",F8="Bags"),Assumptions!$B$4,1)) | Y8: =IFERROR(VLOOKUP(F8,Assumptions!$A$16:$C$20,2,FALSE),0.40) | Z8: =IFERROR(VLOOKUP(F8,Assumptions!$A$16:$C$20,3,FALSE),0.30) | AA8: =IF(P8<>"",P8*X8*W8,IF(L8<>"",L8/(1-Y8),K8)) | AB8: =IF(L8<>"",L8/(1-Z8),"") | AC8: =IF(AB8="",AA8,MAX(AA8,AB8)) | AD8: =IF(AC8="","",AC8*G8) | AE8: =IF(AD8="","",ROUNDUP(AD8,0)-0.01) | AF8: =IF(P8<>"","Competitor-based",IF(L8<>"","Cost+margin","Needs review"))
A9: 7ml-screw-top-jars-with-black-lids | B9: 7ml Glass Jars- Low Profile heavy bottom- Screw Top with Lids | C9: The 7ml Low Profile Heavy Bottom Glass Jar is a lab-grade concentrate container built for extractors, processors, and brands who need packaging that performs on the bench and looks right on the shelf. At 7ml (0.24 fl oz)… | D9: Quantity: 180 / Lid Color: Black / Glass: Frosted | E9: 7MLJAR-02BF | F9: Packaging | G9: 180 | H9: pcs | I9: 14.99 | K9: =IFERROR(I9/G9,"") | L9: =IFERROR(J9/G9,"") | M9: =IFERROR((I9-J9)/I9,"") | N9: 43 | O9: 90 | P9: =IFERROR(N9/O9,"") | S9: =IFERROR(Q9/R9,"") | T9: Observed | U9: https://sodoloco.com/products/low-profile-7ml-glass-jars-child-resistant-black-lid-90 | V9: Low profile 7ml glass jar with black lid; 90 pack listed at $43. | W9: =IF(G9="","",IF(G9<=Assumptions!$B$9,Assumptions!$C$9,IF(G9<=Assumptions!$B$10,Assumptions!$C$10,IF(G9<=Assumptions!$B$11,Assumptions!$C$11,Assumptions!$C$12)))) | X9: =IF(F9="Branded",Assumptions!$B$5,IF(OR(F9="Packaging",F9="Bags"),Assumptions!$B$4,1)) | Y9: =IFERROR(VLOOKUP(F9,Assumptions!$A$16:$C$20,2,FALSE),0.40) | Z9: =IFERROR(VLOOKUP(F9,Assumptions!$A$16:$C$20,3,FALSE),0.30) | AA9: =IF(P9<>"",P9*X9*W9,IF(L9<>"",L9/(1-Y9),K9)) | AB9: =IF(L9<>"",L9/(1-Z9),"") | AC9: =IF(AB9="",AA9,MAX(AA9,AB9)) | AD9: =IF(AC9="","",AC9*G9) | AE9: =IF(AD9="","",ROUNDUP(AD9,0)-0.01) | AF9: =IF(P9<>"","Competitor-based",IF(L9<>"","Cost+margin","Needs review"))
A10: 7ml-screw-top-jars-with-black-lids | B10: 7ml Glass Jars- Low Profile heavy bottom- Screw Top with Lids | C10: The 7ml Low Profile Heavy Bottom Glass Jar is a lab-grade concentrate container built for extractors, processors, and brands who need packaging that performs on the bench and looks right on the shelf. At 7ml (0.24 fl oz)… | D10: Quantity: 450 / Lid Color: Black / Glass: Clear | E10: 7MLJAR-03B | F10: Packaging | G10: 450 | H10: pcs | I10: 49.99 | K10: =IFERROR(I10/G10,"") | L10: =IFERROR(J10/G10,"") | M10: =IFERROR((I10-J10)/I10,"") | N10: 43 | O10: 90 | P10: =IFERROR(N10/O10,"") | S10: =IFERROR(Q10/R10,"") | T10: Observed | U10: https://sodoloco.com/products/low-profile-7ml-glass-jars-child-resistant-black-lid-90 | V10: Low profile 7ml glass jar with black lid; 90 pack listed at $43. | W10: =IF(G10="","",IF(G10<=Assumptions!$B$9,Assumptions!$C$9,IF(G10<=Assumptions!$B$10,Assumptions!$C$10,IF(G10<=Assumptions!$B$11,Assumptions!$C$11,Assumptions!$C$12)))) | X10: =IF(F10="Branded",Assumptions!$B$5,IF(OR(F10="Packaging",F10="Bags"),Assumptions!$B$4,1)) | Y10: =IFERROR(VLOOKUP(F10,Assumptions!$A$16:$C$20,2,FALSE),0.40) | Z10: =IFERROR(VLOOKUP(F10,Assumptions!$A$16:$C$20,3,FALSE),0.30) | AA10: =IF(P10<>"",P10*X10*W10,IF(L10<>"",L10/(1-Y10),K10)) | AB10: =IF(L10<>"",L10/(1-Z10),"") | AC10: =IF(AB10="",AA10,MAX(AA10,AB10)) | AD10: =IF(AC10="","",AC10*G10) | AE10: =IF(AD10="","",ROUNDUP(AD10,0)-0.01) | AF10: =IF(P10<>"","Competitor-based",IF(L10<>"","Cost+margin","Needs review"))
A11: 7ml-screw-top-jars-with-black-lids | B11: 7ml Glass Jars- Low Profile heavy bottom- Screw Top with Lids | C11: The 7ml Low Profile Heavy Bottom Glass Jar is a lab-grade concentrate container built for extractors, processors, and brands who need packaging that performs on the bench and looks right on the shelf. At 7ml (0.24 fl oz)… | D11: Quantity: 450 / Lid Color: Black / Glass: Frosted | E11: 7MLJAR-03BF | F11: Packaging | G11: 450 | H11: pcs | I11: 49.99 | K11: =IFERROR(I11/G11,"") | L11: =IFERROR(J11/G11,"") | M11: =IFERROR((I11-J11)/I11,"") | N11: 43 | O11: 90 | P11: =IFERROR(N11/O11,"") | S11: =IFERROR(Q11/R11,"") | T11: Observed | U11: https://sodoloco.com/products/low-profile-7ml-glass-jars-child-resistant-black-lid-90 | V11: Low profile 7ml glass jar with black lid; 90 pack listed at $43. | W11: =IF(G11="","",IF(G11<=Assumptions!$B$9,Assumptions!$C$9,IF(G11<=Assumptions!$B$10,Assumptions!$C$10,IF(G11<=Assumptions!$B$11,Assumptions!$C$11,Assumptions!$C$12)))) | X11: =IF(F11="Branded",Assumptions!$B$5,IF(OR(F11="Packaging",F11="Bags"),Assumptions!$B$4,1)) | Y11: =IFERROR(VLOOKUP(F11,Assumptions!$A$16:$C$20,2,FALSE),0.40) | Z11: =IFERROR(VLOOKUP(F11,Assumptions!$A$16:$C$20,3,FALSE),0.30) | AA11: =IF(P11<>"",P11*X11*W11,IF(L11<>"",L11/(1-Y11),K11)) | AB11: =IF(L11<>"",L11/(1-Z11),"") | AC11: =IF(AB11="",AA11,MAX(AA11,AB11)) | AD11: =IF(AC11="","",AC11*G11) | AE11: =IF(AD11="","",ROUNDUP(AD11,0)-0.01) | AF11: =IF(P11<>"","Competitor-based",IF(L11<>"","Cost+margin","Needs review"))
A12: 7ml-screw-top-jars-with-black-lids | B12: 7ml Glass Jars- Low Profile heavy bottom- Screw Top with Lids | C12: The 7ml Low Profile Heavy Bottom Glass Jar is a lab-grade concentrate container built for extractors, processors, and brands who need packaging that performs on the bench and looks right on the shelf. At 7ml (0.24 fl oz)… | D12: Quantity: 900 / Lid Color: Black / Glass: Clear | E12: 7MLJAR-04B | F12: Packaging | G12: 900 | H12: pcs | I12: 29.99 | K12: =IFERROR(I12/G12,"") | L12: =IFERROR(J12/G12,"") | M12: =IFERROR((I12-J12)/I12,"") | N12: 43 | O12: 90 | P12: =IFERROR(N12/O12,"") | S12: =IFERROR(Q12/R12,"") | T12: Observed | U12: https://sodoloco.com/products/low-profile-7ml-glass-jars-child-resistant-black-lid-90 | V12: Low profile 7ml glass jar with black lid; 90 pack listed at $43. | W12: =IF(G12="","",IF(G12<=Assumptions!$B$9,Assumptions!$C$9,IF(G12<=Assumptions!$B$10,Assumptions!$C$10,IF(G12<=Assumptions!$B$11,Assumptions!$C$11,Assumptions!$C$12)))) | X12: =IF(F12="Branded",Assumptions!$B$5,IF(OR(F12="Packaging",F12="Bags"),Assumptions!$B$4,1)) | Y12: =IFERROR(VLOOKUP(F12,Assumptions!$A$16:$C$20,2,FALSE),0.40) | Z12: =IFERROR(VLOOKUP(F12,Assumptions!$A$16:$C$20,3,FALSE),0.30) | AA12: =IF(P12<>"",P12*X12*W12,IF(L12<>"",L12/(1-Y12),K12)) | AB12: =IF(L12<>"",L12/(1-Z12),"") | AC12: =IF(AB12="",AA12,MAX(AA12,AB12)) | AD12: =IF(AC12="","",AC12*G12) | AE12: =IF(AD12="","",ROUNDUP(AD12,0)-0.01) | AF12: =IF(P12<>"","Competitor-based",IF(L12<>"","Cost+margin","Needs review"))
A13: 7ml-screw-top-jars-with-black-lids | B13: 7ml Glass Jars- Low Profile heavy bottom- Screw Top with Lids | C13: The 7ml Low Profile Heavy Bottom Glass Jar is a lab-grade concentrate container built for extractors, processors, and brands who need packaging that performs on the bench and looks right on the shelf. At 7ml (0.24 fl oz)… | D13: Quantity: 900 / Lid Color: Black / Glass: Frosted | E13: 7MLJAR-04BF | F13: Packaging | G13: 900 | H13: pcs | I13: 14.99 | K13: =IFERROR(I13/G13,"") | L13: =IFERROR(J13/G13,"") | M13: =IFERROR((I13-J13)/I13,"") | N13: 43 | O13: 90 | P13: =IFERROR(N13/O13,"") | S13: =IFERROR(Q13/R13,"") | T13: Observed | U13: https://sodoloco.com/products/low-profile-7ml-glass-jars-child-resistant-black-lid-90 | V13: Low profile 7ml glass jar with black lid; 90 pack listed at $43. | W13: =IF(G13="","",IF(G13<=Assumptions!$B$9,Assumptions!$C$9,IF(G13<=Assumptions!$B$10,Assumptions!$C$10,IF(G13<=Assumptions!$B$11,Assumptions!$C$11,Assumptions!$C$12)))) | X13: =IF(F13="Branded",Assumptions!$B$5,IF(OR(F13="Packaging",F13="Bags"),Assumptions!$B$4,1)) | Y13: =IFERROR(VLOOKUP(F13,Assumptions!$A$16:$C$20,2,FALSE),0.40) | Z13: =IFERROR(VLOOKUP(F13,Assumptions!$A$16:$C$20,3,FALSE),0.30) | AA13: =IF(P13<>"",P13*X13*W13,IF(L13<>"",L13/(1-Y13),K13)) | AB13: =IF(L13<>"",L13/(1-Z13),"") | AC13: =IF(AB13="",AA13,MAX(AA13,AB13)) | AD13: =IF(AC13="","",AC13*G13) | AE13: =IF(AD13="","",ROUNDUP(AD13,0)-0.01) | AF13: =IF(P13<>"","Competitor-based",IF(L13<>"","Cost+margin","Needs review"))
A14: 7ml-screw-top-jars-with-black-lids | B14: 7ml Glass Jars- Low Profile heavy bottom- Screw Top with Lids | C14: The 7ml Low Profile Heavy Bottom Glass Jar is a lab-grade concentrate container built for extractors, processors, and brands who need packaging that performs on the bench and looks right on the shelf. At 7ml (0.24 fl oz)… | D14: Quantity: 2700 / Lid Color: Black / Glass: Clear | E14: 7MLJAR-09B | F14: Packaging | G14: 2700 | H14: pcs | I14: 49.99 | K14: =IFERROR(I14/G14,"") | L14: =IFERROR(J14/G14,"") | M14: =IFERROR((I14-J14)/I14,"") | N14: 43 | O14: 90 | P14: =IFERROR(N14/O14,"") | S14: =IFERROR(Q14/R14,"") | T14: Observed | U14: https://sodoloco.com/products/low-profile-7ml-glass-jars-child-resistant-black-lid-90 | V14: Low profile 7ml glass jar with black lid; 90 pack listed at $43. | W14: =IF(G14="","",IF(G14<=Assumptions!$B$9,Assumptions!$C$9,IF(G14<=Assumptions!$B$10,Assumptions!$C$10,IF(G14<=Assumptions!$B$11,Assumptions!$C$11,Assumptions!$C$12)))) | X14: =IF(F14="Branded",Assumptions!$B$5,IF(OR(F14="Packaging",F14="Bags"),Assumptions!$B$4,1)) | Y14: =IFERROR(VLOOKUP(F14,Assumptions!$A$16:$C$20,2,FALSE),0.40) | Z14: =IFERROR(VLOOKUP(F14,Assumptions!$A$16:$C$20,3,FALSE),0.30) | AA14: =IF(P14<>"",P14*X14*W14,IF(L14<>"",L14/(1-Y14),K14)) | AB14: =IF(L14<>"",L14/(1-Z14),"") | AC14: =IF(AB14="",AA14,MAX(AA14,AB14)) | AD14: =IF(AC14="","",AC14*G14) | AE14: =IF(AD14="","",ROUNDUP(AD14,0)-0.01) | AF14: =IF(P14<>"","Competitor-based",IF(L14<>"","Cost+margin","Needs review"))
A15: 7ml-screw-top-jars-with-black-lids | B15: 7ml Glass Jars- Low Profile heavy bottom- Screw Top with Lids | C15: The 7ml Low Profile Heavy Bottom Glass Jar is a lab-grade concentrate container built for extractors, processors, and brands who need packaging that performs on the bench and looks right on the shelf. At 7ml (0.24 fl oz)… | D15: Quantity: 2700 / Lid Color: Black / Glass: Frosted | E15: 7MLJAR-09BF | F15: Packaging | G15: 2700 | H15: pcs | I15: 44.99 | K15: =IFERROR(I15/G15,"") | L15: =IFERROR(J15/G15,"") | M15: =IFERROR((I15-J15)/I15,"") | N15: 43 | O15: 90 | P15: =IFERROR(N15/O15,"") | S15: =IFERROR(Q15/R15,"") | T15: Observed | U15: https://sodoloco.com/products/low-profile-7ml-glass-jars-child-resistant-black-lid-90 | V15: Low profile 7ml glass jar with black lid; 90 pack listed at $43. | W15: =IF(G15="","",IF(G15<=Assumptions!$B$9,Assumptions!$C$9,IF(G15<=Assumptions!$B$10,Assumptions!$C$10,IF(G15<=Assumptions!$B$11,Assumptions!$C$11,Assumptions!$C$12)))) | X15: =IF(F15="Branded",Assumptions!$B$5,IF(OR(F15="Packaging",F15="Bags"),Assumptions!$B$4,1)) | Y15: =IFERROR(VLOOKUP(F15,Assumptions!$A$16:$C$20,2,FALSE),0.40) | Z15: =IFERROR(VLOOKUP(F15,Assumptions!$A$16:$C$20,3,FALSE),0.30) | AA15: =IF(P15<>"",P15*X15*W15,IF(L15<>"",L15/(1-Y15),K15)) | AB15: =IF(L15<>"",L15/(1-Z15),"") | AC15: =IF(AB15="",AA15,MAX(AA15,AB15)) | AD15: =IF(AC15="","",AC15*G15) | AE15: =IF(AD15="","",ROUNDUP(AD15,0)-0.01) | AF15: =IF(P15<>"","Competitor-based",IF(L15<>"","Cost+margin","Needs review"))
A16: 7ml-screw-top-jars-with-black-lids | B16: 7ml Glass Jars- Low Profile heavy bottom- Screw Top with Lids | C16: The 7ml Low Profile Heavy Bottom Glass Jar is a lab-grade concentrate container built for extractors, processors, and brands who need packaging that performs on the bench and looks right on the shelf. At 7ml (0.24 fl oz)… | D16: Quantity: 4500 / Lid Color: Black / Glass: Clear | E16: 7MLJAR-05B | F16: Packaging | G16: 4500 | H16: pcs | I16: 65 | K16: =IFERROR(I16/G16,"") | L16: =IFERROR(J16/G16,"") | M16: =IFERROR((I16-J16)/I16,"") | N16: 43 | O16: 90 | P16: =IFERROR(N16/O16,"") | S16: =IFERROR(Q16/R16,"") | T16: Observed | U16: https://sodoloco.com/products/low-profile-7ml-glass-jars-child-resistant-black-lid-90 | V16: Low profile 7ml glass jar with black lid; 90 pack listed at $43. | W16: =IF(G16="","",IF(G16<=Assumptions!$B$9,Assumptions!$C$9,IF(G16<=Assumptions!$B$10,Assumptions!$C$10,IF(G16<=Assumptions!$B$11,Assumptions!$C$11,Assumptions!$C$12)))) | X16: =IF(F16="Branded",Assumptions!$B$5,IF(OR(F16="Packaging",F16="Bags"),Assumptions!$B$4,1)) | Y16: =IFERROR(VLOOKUP(F16,Assumptions!$A$16:$C$20,2,FALSE),0.40) | Z16: =IFERROR(VLOOKUP(F16,Assumptions!$A$16:$C$20,3,FALSE),0.30) | AA16: =IF(P16<>"",P16*X16*W16,IF(L16<>"",L16/(1-Y16),K16)) | AB16: =IF(L16<>"",L16/(1-Z16),"") | AC16: =IF(AB16="",AA16,MAX(AA16,AB16)) | AD16: =IF(AC16="","",AC16*G16) | AE16: =IF(AD16="","",ROUNDUP(AD16,0)-0.01) | AF16: =IF(P16<>"","Competitor-based",IF(L16<>"","Cost+margin","Needs review"))
A17: 7ml-screw-top-jars-with-black-lids | B17: 7ml Glass Jars- Low Profile heavy bottom- Screw Top with Lids | C17: The 7ml Low Profile Heavy Bottom Glass Jar is a lab-grade concentrate container built for extractors, processors, and brands who need packaging that performs on the bench and looks right on the shelf. At 7ml (0.24 fl oz)… | D17: Quantity: 4500 / Lid Color: Black / Glass: Frosted | E17: 7MLJAR-05BF | F17: Packaging | G17: 4500 | H17: pcs | I17: 49.99 | K17: =IFERROR(I17/G17,"") | L17: =IFERROR(J17/G17,"") | M17: =IFERROR((I17-J17)/I17,"") | N17: 43 | O17: 90 | P17: =IFERROR(N17/O17,"") | S17: =IFERROR(Q17/R17,"") | T17: Observed | U17: https://sodoloco.com/products/low-profile-7ml-glass-jars-child-resistant-black-lid-90 | V17: Low profile 7ml glass jar with black lid; 90 pack listed at $43. | W17: =IF(G17="","",IF(G17<=Assumptions!$B$9,Assumptions!$C$9,IF(G17<=Assumptions!$B$10,Assumptions!$C$10,IF(G17<=Assumptions!$B$11,Assumptions!$C$11,Assumptions!$C$12)))) | X17: =IF(F17="Branded",Assumptions!$B$5,IF(OR(F17="Packaging",F17="Bags"),Assumptions!$B$4,1)) | Y17: =IFERROR(VLOOKUP(F17,Assumptions!$A$16:$C$20,2,FALSE),0.40) | Z17: =IFERROR(VLOOKUP(F17,Assumptions!$A$16:$C$20,3,FALSE),0.30) | AA17: =IF(P17<>"",P17*X17*W17,IF(L17<>"",L17/(1-Y17),K17)) | AB17: =IF(L17<>"",L17/(1-Z17),"") | AC17: =IF(AB17="",AA17,MAX(AA17,AB17)) | AD17: =IF(AC17="","",AC17*G17) | AE17: =IF(AD17="","",ROUNDUP(AD17,0)-0.01) | AF17: =IF(P17<>"","Competitor-based",IF(L17<>"","Cost+margin","Needs review"))
... A19: 7ml-screw-top-jars-with-black-lids | B19: 7ml Glass Jars- Low Profile heavy bottom- Screw Top with Lids | C19: The 7ml Low Profile Heavy Bottom Glass Jar is a lab-grade concentrate container built for extractors, processors, and brands who need packaging that performs on the bench and looks right on the shelf. At 7ml (0.24 fl oz)… | D19: Quantity: 9900 / Lid Color: Black / Glass: Frosted | E19: 7MLJAR-06BF | F19: Packaging | G19: 9900 | H19: pcs | I19: 79.99 | K19: =IFERROR(I19/G19,"") | L19: =IFERROR(J19/G19,"") | M19: =IFERROR((I19-J19)/I19,"") | N19: 43 | O19: 90 | P19: =IFERROR(N19/O19,"") | S19: =IFERROR(Q19/R19,"") | T19: Observed | U19: https://sodoloco.com/products/low-profile-7ml-glass-jars-child-resistant-black-lid-90 | V19: Low profile 7ml glass jar with black lid; 90 pack listed at $43. | W19: =IF(G19="","",IF(G19<=Assumptions!$B$9,Assumptions!$C$9,IF(G19<=Assumptions!$B$10,Assumptions!$C$10,IF(G19<=Assumptions!$B$11,Assumptions!$C$11,Assumptions!$C$12)))) | X19: =IF(F19="Branded",Assumptions!$B$5,IF(OR(F19="Packaging",F19="Bags"),Assumptions!$B$4,1)) | Y19: =IFERROR(VLOOKUP(F19,Assumptions!$A$16:$C$20,2,FALSE),0.40) | Z19: =IFERROR(VLOOKUP(F19,Assumptions!$A$16:$C$20,3,FALSE),0.30) | AA19: =IF(P19<>"",P19*X19*W19,IF(L19<>"",L19/(1-Y19),K19)) | AB19: =IF(L19<>"",L19/(1-Z19),"") | AC19: =IF(AB19="",AA19,MAX(AA19,AB19)) | AD19: =IF(AC19="","",AC19*G19) | AE19: =IF(AD19="","",ROUNDUP(AD19,0)-0.01) | AF19: =IF(P19<>"","Competitor-based",IF(L19<>"","Cost+margin","Needs review"))
A20: blank-boxes-for-7ml-jars | B20: Blank Boxes for Jars | C20: Oil Slick Blank Boxes for Jars are clean, retail-ready outer boxes for your concentrate jars, built for brands and extractors who want pro packaging without being locked into pre-printed designs. Sized to fit 5ml, 6ml, 7… | D20: Size: 7ml / Quantity: 50 / Color: Black | F20: Packaging | G20: 50 | H20: pcs | I20: 29.99 | K20: =IFERROR(I20/G20,"") | L20: =IFERROR(J20/G20,"") | M20: =IFERROR((I20-J20)/I20,"") | P20: =IFERROR(N20/O20,"") | S20: =IFERROR(Q20/R20,"") | W20: =IF(G20="","",IF(G20<=Assumptions!$B$9,Assumptions!$C$9,IF(G20<=Assumptions!$B$10,Assumptions!$C$10,IF(G20<=Assumptions!$B$11,Assumptions!$C$11,Assumptions!$C$12)))) | X20: =IF(F20="Branded",Assumptions!$B$5,IF(OR(F20="Packaging",F20="Bags"),Assumptions!$B$4,1)) | Y20: =IFERROR(VLOOKUP(F20,Assumptions!$A$16:$C$20,2,FALSE),0.40) | Z20: =IFERROR(VLOOKUP(F20,Assumptions!$A$16:$C$20,3,FALSE),0.30) | AA20: =IF(P20<>"",P20*X20*W20,IF(L20<>"",L20/(1-Y20),K20)) | AB20: =IF(L20<>"",L20/(1-Z20),"") | AC20: =IF(AB20="",AA20,MAX(AA20,AB20)) | AD20: =IF(AC20="","",AC20*G20) | AE20: =IF(AD20="","",ROUNDUP(AD20,0)-0.01) | AF20: =IF(P20<>"","Competitor-based",IF(L20<>"","Cost+margin","Needs review"))
A21: blank-boxes-for-7ml-jars | B21: Blank Boxes for Jars | C21: Oil Slick Blank Boxes for Jars are clean, retail-ready outer boxes for your concentrate jars, built for brands and extractors who want pro packaging without being locked into pre-printed designs. Sized to fit 5ml, 6ml, 7… | D21: Size: 7ml / Quantity: 500 / Color: Black | E21: BOX FOR JAR 7ML 500 | F21: Packaging | G21: 500 | H21: pcs | I21: 75 | J21: 258 | K21: =IFERROR(I21/G21,"") | L21: =IFERROR(J21/G21,"") | M21: =IFERROR((I21-J21)/I21,"") | P21: =IFERROR(N21/O21,"") | S21: =IFERROR(Q21/R21,"") | W21: =IF(G21="","",IF(G21<=Assumptions!$B$9,Assumptions!$C$9,IF(G21<=Assumptions!$B$10,Assumptions!$C$10,IF(G21<=Assumptions!$B$11,Assumptions!$C$11,Assumptions!$C$12)))) | X21: =IF(F21="Branded",Assumptions!$B$5,IF(OR(F21="Packaging",F21="Bags"),Assumptions!$B$4,1)) | Y21: =IFERROR(VLOOKUP(F21,Assumptions!$A$16:$C$20,2,FALSE),0.40) | Z21: =IFERROR(VLOOKUP(F21,Assumptions!$A$16:$C$20,3,FALSE),0.30) | AA21: =IF(P21<>"",P21*X21*W21,IF(L21<>"",L21/(1-Y21),K21)) | AB21: =IF(L21<>"",L21/(1-Z21),"") | AC21: =IF(AB21="",AA21,MAX(AA21,AB21)) | AD21: =IF(AC21="","",AC21*G21) | AE21: =IF(AD21="","",ROUNDUP(AD21,0)-0.01) | AF21: =IF(P21<>"","Competitor-based",IF(L21<>"","Cost+margin","Needs review"))
A22: blank-boxes-for-7ml-jars | B22: Blank Boxes for Jars | C22: Oil Slick Blank Boxes for Jars are clean, retail-ready outer boxes for your concentrate jars, built for brands and extractors who want pro packaging without being locked into pre-printed designs. Sized to fit 5ml, 6ml, 7… | D22: Size: 5ml / Quantity: 1000 / Color: Black | E22: BOX FOR JAR 5ml 1000 | F22: Packaging | G22: 1000 | H22: pcs | I22: 12.99 | K22: =IFERROR(I22/G22,"") | L22: =IFERROR(J22/G22,"") | M22: =IFERROR((I22-J22)/I22,"") | P22: =IFERROR(N22/O22,"") | S22: =IFERROR(Q22/R22,"") | W22: =IF(G22="","",IF(G22<=Assumptions!$B$9,Assumptions!$C$9,IF(G22<=Assumptions!$B$10,Assumptions!$C$10,IF(G22<=Assumptions!$B$11,Assumptions!$C$11,Assumptions!$C$12)))) | X22: =IF(F22="Branded",Assumptions!$B$5,IF(OR(F22="Packaging",F22="Bags"),Assumptions!$B$4,1)) | Y22: =IFERROR(VLOOKUP(F22,Assumptions!$A$16:$C$20,2,FALSE),0.40) | Z22: =IFERROR(VLOOKUP(F22,Assumptions!$A$16:$C$20,3,FALSE),0.30) | AA22: =IF(P22<>"",P22*X22*W22,IF(L22<>"",L22/(1-Y22),K22)) | AB22: =IF(L22<>"",L22/(1-Z22),"") | AC22: =IF(AB22="",AA22,MAX(AA22,AB22)) | AD22: =IF(AC22="","",AC22*G22) | AE22: =IF(AD22="","",ROUNDUP(AD22,0)-0.01) | AF22: =IF(P22<>"","Competitor-based",IF(L22<>"","Cost+margin","Needs review"))
A23: blank-boxes-for-7ml-jars | B23: Blank Boxes for Jars | C23: Oil Slick Blank Boxes for Jars are clean, retail-ready outer boxes for your concentrate jars, built for brands and extractors who want pro packaging without being locked into pre-printed designs. Sized to fit 5ml, 6ml, 7… | D23: Size: 5ml / Quantity: 1000 / Color: White | E23: BOX FOR JAR 5ML 1000 | F23: Packaging | G23: 1000 | H23: pcs | I23: 12.99 | K23: =IFERROR(I23/G23,"") | L23: =IFERROR(J23/G23,"") | M23: =IFERROR((I23-J23)/I23,"") | P23: =IFERROR(N23/O23,"") | S23: =IFERROR(Q23/R23,"") | W23: =IF(G23="","",IF(G23<=Assumptions!$B$9,Assumptions!$C$9,IF(G23<=Assumptions!$B$10,Assumptions!$C$10,IF(G23<=Assumptions!$B$11,Assumptions!$C$11,Assumptions!$C$12)))) | X23: =IF(F23="Branded",Assumptions!$B$5,IF(OR(F23="Packaging",F23="Bags"),Assumptions!$B$4,1)) | Y23: =IFERROR(VLOOKUP(F23,Assumptions!$A$16:$C$20,2,FALSE),0.40) | Z23: =IFERROR(VLOOKUP(F23,Assumptions!$A$16:$C$20,3,FALSE),0.30) | AA23: =IF(P23<>"",P23*X23*W23,IF(L23<>"",L23/(1-Y23),K23)) | AB23: =IF(L23<>"",L23/(1-Z23),"") | AC23: =IF(AB23="",AA23,MAX(AA23,AB23)) | AD23: =IF(AC23="","",AC23*G23) | AE23: =IF(AD23="","",ROUNDUP(AD23,0)-0.01) | AF23: =IF(P23<>"","Competitor-based",IF(L23<>"","Cost+margin","Needs review"))
A24: blank-boxes-for-7ml-jars | B24: Blank Boxes for Jars | C24: Oil Slick Blank Boxes for Jars are clean, retail-ready outer boxes for your concentrate jars, built for brands and extractors who want pro packaging without being locked into pre-printed designs. Sized to fit 5ml, 6ml, 7… | D24: Size: 6ml / Quantity: 1000 / Color: Black | E24: BOX FOR JAR 6ML 1000 | F24: Packaging | G24: 1000 | H24: pcs | I24: 10.99 | K24: =IFERROR(I24/G24,"") | L24: =IFERROR(J24/G24,"") | M24: =IFERROR((I24-J24)/I24,"") | P24: =IFERROR(N24/O24,"") | S24: =IFERROR(Q24/R24,"") | W24: =IF(G24="","",IF(G24<=Assumptions!$B$9,Assumptions!$C$9,IF(G24<=Assumptions!$B$10,Assumptions!$C$10,IF(G24<=Assumptions!$B$11,Assumptions!$C$11,Assumptions!$C$12)))) | X24: =IF(F24="Branded",Assumptions!$B$5,IF(OR(F24="Packaging",F24="Bags"),Assumptions!$B$4,1)) | Y24: =IFERROR(VLOOKUP(F24,Assumptions!$A$16:$C$20,2,FALSE),0.40) | Z24: =IFERROR(VLOOKUP(F24,Assumptions!$A$16:$C$20,3,FALSE),0.30) | AA24: =IF(P24<>"",P24*X24*W24,IF(L24<>"",L24/(1-Y24),K24)) | AB24: =IF(L24<>"",L24/(1-Z24),"") | AC24: =IF(AB24="",AA24,MAX(AA24,AB24)) | AD24: =IF(AC24="","",AC24*G24) | AE24: =IF(AD24="","",ROUNDUP(AD24,0)-0.01) | AF24: =IF(P24<>"","Competitor-based",IF(L24<>"","Cost+margin","Needs review"))
A25: blank-boxes-for-7ml-jars | B25: Blank Boxes for Jars | C25: Oil Slick Blank Boxes for Jars are clean, retail-ready outer boxes for your concentrate jars, built for brands and extractors who want pro packaging without being locked into pre-printed designs. Sized to fit 5ml, 6ml, 7… | D25: Size: 6ml / Quantity: 1000 / Color: White | E25: BOX FOR JAR 6ML 1000 | F25: Packaging | G25: 1000 | H25: pcs | I25: 19.99 | K25: =IFERROR(I25/G25,"") | L25: =IFERROR(J25/G25,"") | M25: =IFERROR((I25-J25)/I25,"") | P25: =IFERROR(N25/O25,"") | S25: =IFERROR(Q25/R25,"") | W25: =IF(G25="","",IF(G25<=Assumptions!$B$9,Assumptions!$C$9,IF(G25<=Assumptions!$B$10,Assumptions!$C$10,IF(G25<=Assumptions!$B$11,Assumptions!$C$11,Assumptions!$C$12)))) | X25: =IF(F25="Branded",Assumptions!$B$5,IF(OR(F25="Packaging",F25="Bags"),Assumptions!$B$4,1)) | Y25: =IFERROR(VLOOKUP(F25,Assumptions!$A$16:$C$20,2,FALSE),0.40) | Z25: =IFERROR(VLOOKUP(F25,Assumptions!$A$16:$C$20,3,FALSE),0.30) | AA25: =IF(P25<>"",P25*X25*W25,IF(L25<>"",L25/(1-Y25),K25)) | AB25: =IF(L25<>"",L25/(1-Z25),"") | AC25: =IF(AB25="",AA25,MAX(AA25,AB25)) | AD25: =IF(AC25="","",AC25*G25) | AE25: =IF(AD25="","",ROUNDUP(AD25,0)-0.01) | AF25: =IF(P25<>"","Competitor-based",IF(L25<>"","Cost+margin","Needs review"))
A26: blank-boxes-for-7ml-jars | B26: Blank Boxes for Jars | C26: Oil Slick Blank Boxes for Jars are clean, retail-ready outer boxes for your concentrate jars, built for brands and extractors who want pro packaging without being locked into pre-printed designs. Sized to fit 5ml, 6ml, 7… | D26: Size: 7ml / Quantity: 1000 / Color: Black | E26: BOX FOR JAR 7ML 1000 | F26: Packaging | G26: 1000 | H26: pcs | I26: 599.99 | J26: 444 | K26: =IFERROR(I26/G26,"") | L26: =IFERROR(J26/G26,"") | M26: =IFERROR((I26-J26)/I26,"") | P26: =IFERROR(N26/O26,"") | S26: =IFERROR(Q26/R26,"") | W26: =IF(G26="","",IF(G26<=Assumptions!$B$9,Assumptions!$C$9,IF(G26<=Assumptions!$B$10,Assumptions!$C$10,IF(G26<=Assumptions!$B$11,Assumptions!$C$11,Assumptions!$C$12)))) | X26: =IF(F26="Branded",Assumptions!$B$5,IF(OR(F26="Packaging",F26="Bags"),Assumptions!$B$4,1)) | Y26: =IFERROR(VLOOKUP(F26,Assumptions!$A$16:$C$20,2,FALSE),0.40) | Z26: =IFERROR(VLOOKUP(F26,Assumptions!$A$16:$C$20,3,FALSE),0.30) | AA26: =IF(P26<>"",P26*X26*W26,IF(L26<>"",L26/(1-Y26),K26)) | AB26: =IF(L26<>"",L26/(1-Z26),"") | AC26: =IF(AB26="",AA26,MAX(AA26,AB26)) | AD26: =IF(AC26="","",AC26*G26) | AE26: =IF(AD26="","",ROUNDUP(AD26,0)-0.01) | AF26: =IF(P26<>"","Competitor-based",IF(L26<>"","Cost+margin","Needs review"))
A27: blank-boxes-for-7ml-jars | B27: Blank Boxes for Jars | C27: Oil Slick Blank Boxes for Jars are clean, retail-ready outer boxes for your concentrate jars, built for brands and extractors who want pro packaging without being locked into pre-printed designs. Sized to fit 5ml, 6ml, 7… | D27: Size: 7ml / Quantity: 1000 / Color: White | E27: BOX FOR JAR 7ML 1000 | F27: Packaging | G27: 1000 | H27: pcs | I27: 9.99 | J27: 335 | K27: =IFERROR(I27/G27,"") | L27: =IFERROR(J27/G27,"") | M27: =IFERROR((I27-J27)/I27,"") | P27: =IFERROR(N27/O27,"") | S27: =IFERROR(Q27/R27,"") | W27: =IF(G27="","",IF(G27<=Assumptions!$B$9,Assumptions!$C$9,IF(G27<=Assumptions!$B$10,Assumptions!$C$10,IF(G27<=Assumptions!$B$11,Assumptions!$C$11,Assumptions!$C$12)))) | X27: =IF(F27="Branded",Assumptions!$B$5,IF(OR(F27="Packaging",F27="Bags"),Assumptions!$B$4,1)) | Y27: =IFERROR(VLOOKUP(F27,Assumptions!$A$16:$C$20,2,FALSE),0.40) | Z27: =IFERROR(VLOOKUP(F27,Assumptions!$A$16:$C$20,3,FALSE),0.30) | AA27: =IF(P27<>"",P27*X27*W27,IF(L27<>"",L27/(1-Y27),K27)) | AB27: =IF(L27<>"",L27/(1-Z27),"") | AC27: =IF(AB27="",AA27,MAX(AA27,AB27)) | AD27: =IF(AC27="","",AC27*G27) | AE27: =IF(AD27="","",ROUNDUP(AD27,0)-0.01) | AF27: =IF(P27<>"","Competitor-based",IF(L27<>"","Cost+margin","Needs review"))
A28: blank-boxes-for-7ml-jars | B28: Blank Boxes for Jars | C28: Oil Slick Blank Boxes for Jars are clean, retail-ready outer boxes for your concentrate jars, built for brands and extractors who want pro packaging without being locked into pre-printed designs. Sized to fit 5ml, 6ml, 7… | D28: Size: 9ml / Quantity: 1000 / Color: Black | E28: BOX FOR JAR 9ML 1000 | F28: Packaging | G28: 1000 | H28: pcs | I28: 24.99 | J28: 553 | K28: =IFERROR(I28/G28,"") | L28: =IFERROR(J28/G28,"") | M28: =IFERROR((I28-J28)/I28,"") | P28: =IFERROR(N28/O28,"") | S28: =IFERROR(Q28/R28,"") | W28: =IF(G28="","",IF(G28<=Assumptions!$B$9,Assumptions!$C$9,IF(G28<=Assumptions!$B$10,Assumptions!$C$10,IF(G28<=Assumptions!$B$11,Assumptions!$C$11,Assumptions!$C$12)))) | X28: =IF(F28="Branded",Assumptions!$B$5,IF(OR(F28="Packaging",F28="Bags"),Assumptions!$B$4,1)) | Y28: =IFERROR(VLOOKUP(F28,Assumptions!$A$16:$C$20,2,FALSE),0.40) | Z28: =IFERROR(VLOOKUP(F28,Assumptions!$A$16:$C$20,3,FALSE),0.30) | AA28: =IF(P28<>"",P28*X28*W28,IF(L28<>"",L28/(1-Y28),K28)) | AB28: =IF(L28<>"",L28/(1-Z28),"") | AC28: =IF(AB28="",AA28,MAX(AA28,AB28)) | AD28: =IF(AC28="","",AC28*G28) | AE28: =IF(AD28="","",ROUNDUP(AD28,0)-0.01) | AF28: =IF(P28<>"","Competitor-based",IF(L28<>"","Cost+margin","Needs review"))
A29: blank-boxes-for-7ml-jars | B29: Blank Boxes for Jars | C29: Oil Slick Blank Boxes for Jars are clean, retail-ready outer boxes for your concentrate jars, built for brands and extractors who want pro packaging without being locked into pre-printed designs. Sized to fit 5ml, 6ml, 7… | D29: Size: 6ml / Quantity: 5000 / Color: White | E29: BOX FOR JAR 6ML 5000 | F29: Packaging | G29: 5000 | H29: pcs | I29: 12.99 | K29: =IFERROR(I29/G29,"") | L29: =IFERROR(J29/G29,"") | M29: =IFERROR((I29-J29)/I29,"") | P29: =IFERROR(N29/O29,"") | S29: =IFERROR(Q29/R29,"") | W29: =IF(G29="","",IF(G29<=Assumptions!$B$9,Assumptions!$C$9,IF(G29<=Assumptions!$B$10,Assumptions!$C$10,IF(G29<=Assumptions!$B$11,Assumptions!$C$11,Assumptions!$C$12)))) | X29: =IF(F29="Branded",Assumptions!$B$5,IF(OR(F29="Packaging",F29="Bags"),Assumptions!$B$4,1)) | Y29: =IFERROR(VLOOKUP(F29,Assumptions!$A$16:$C$20,2,FALSE),0.40) | Z29: =IFERROR(VLOOKUP(F29,Assumptions!$A$16:$C$20,3,FALSE),0.30) | AA29: =IF(P29<>"",P29*X29*W29,IF(L29<>"",L29/(1-Y29),K29)) | AB29: =IF(L29<>"",L29/(1-Z29),"") | AC29: =IF(AB29="",AA29,MAX(AA29,AB29)) | AD29: =IF(AC29="","",AC29*G29) | AE29: =IF(AD29="","",ROUNDUP(AD29,0)-0.01) | AF29: =IF(P29<>"","Competitor-based",IF(L29<>"","Cost+margin","Needs review"))
A30: blank-boxes-for-7ml-jars | B30: Blank Boxes for Jars | C30: Oil Slick Blank Boxes for Jars are clean, retail-ready outer boxes for your concentrate jars, built for brands and extractors who want pro packaging without being locked into pre-printed designs. Sized to fit 5ml, 6ml, 7… | D30: Size: 5ml / Quantity: 5000 / Color: Black | E30: BOX FOR JAR 5ML 5000 | F30: Packaging | G30: 5000 | H30: pcs | I30: 9.99 | K30: =IFERROR(I30/G30,"") | L30: =IFERROR(J30/G30,"") | M30: =IFERROR((I30-J30)/I30,"") | P30: =IFERROR(N30/O30,"") | S30: =IFERROR(Q30/R30,"") | W30: =IF(G30="","",IF(G30<=Assumptions!$B$9,Assumptions!$C$9,IF(G30<=Assumptions!$B$10,Assumptions!$C$10,IF(G30<=Assumptions!$B$11,Assumptions!$C$11,Assumptions!$C$12)))) | X30: =IF(F30="Branded",Assumptions!$B$5,IF(OR(F30="Packaging",F30="Bags"),Assumptions!$B$4,1)) | Y30: =IFERROR(VLOOKUP(F30,Assumptions!$A$16:$C$20,2,FALSE),0.40) | Z30: =IFERROR(VLOOKUP(F30,Assumptions!$A$16:$C$20,3,FALSE),0.30) | AA30: =IF(P30<>"",P30*X30*W30,IF(L30<>"",L30/(1-Y30),K30)) | AB30: =IF(L30<>"",L30/(1-Z30),"") | AC30: =IF(AB30="",AA30,MAX(AA30,AB30)) | AD30: =IF(AC30="","",AC30*G30) | AE30: =IF(AD30="","",ROUNDUP(AD30,0)-0.01) | AF30: =IF(P30<>"","Competitor-based",IF(L30<>"","Cost+margin","Needs review"))
A31: blank-boxes-for-7ml-jars | B31: Blank Boxes for Jars | C31: Oil Slick Blank Boxes for Jars are clean, retail-ready outer boxes for your concentrate jars, built for brands and extractors who want pro packaging without being locked into pre-printed designs. Sized to fit 5ml, 6ml, 7… | D31: Size: 6ml / Quantity: 10000 / Color: Black | E31: BOX FOR JAR 6ML 10000 | F31: Packaging | G31: 10000 | H31: pcs | I31: 599.99 | K31: =IFERROR(I31/G31,"") | L31: =IFERROR(J31/G31,"") | M31: =IFERROR((I31-J31)/I31,"") | P31: =IFERROR(N31/O31,"") | S31: =IFERROR(Q31/R31,"") | W31: =IF(G31="","",IF(G31<=Assumptions!$B$9,Assumptions!$C$9,IF(G31<=Assumptions!$B$10,Assumptions!$C$10,IF(G31<=Assumptions!$B$11,Assumptions!$C$11,Assumptions!$C$12)))) | X31: =IF(F31="Branded",Assumptions!$B$5,IF(OR(F31="Packaging",F31="Bags"),Assumptions!$B$4,1)) | Y31: =IFERROR(VLOOKUP(F31,Assumptions!$A$16:$C$20,2,FALSE),0.40) | Z31: =IFERROR(VLOOKUP(F31,Assumptions!$A$16:$C$20,3,FALSE),0.30) | AA31: =IF(P31<>"",P31*X31*W31,IF(L31<>"",L31/(1-Y31),K31)) | AB31: =IF(L31<>"",L31/(1-Z31),"") | AC31: =IF(AB31="",AA31,MAX(AA31,AB31)) | AD31: =IF(AC31="","",AC31*G31) | AE31: =IF(AD31="","",ROUNDUP(AD31,0)-0.01) | AF31: =IF(P31<>"","Competitor-based",IF(L31<>"","Cost+margin","Needs review"))
A32: blank-boxes-for-7ml-jars | B32: Blank Boxes for Jars | C32: Oil Slick Blank Boxes for Jars are clean, retail-ready outer boxes for your concentrate jars, built for brands and extractors who want pro packaging without being locked into pre-printed designs. Sized to fit 5ml, 6ml, 7… | D32: Size: 5ml / Quantity: 5000 / Color: White | E32: BOX FOR JAR 5ML 5000 | F32: Packaging | G32: 5000 | H32: pcs | I32: 12.99 | K32: =IFERROR(I32/G32,"") | L32: =IFERROR(J32/G32,"") | M32: =IFERROR((I32-J32)/I32,"") | P32: =IFERROR(N32/O32,"") | S32: =IFERROR(Q32/R32,"") | W32: =IF(G32="","",IF(G32<=Assumptions!$B$9,Assumptions!$C$9,IF(G32<=Assumptions!$B$10,Assumptions!$C$10,IF(G32<=Assumptions!$B$11,Assumptions!$C$11,Assumptions!$C$12)))) | X32: =IF(F32="Branded",Assumptions!$B$5,IF(OR(F32="Packaging",F32="Bags"),Assumptions!$B$4,1)) | Y32: =IFERROR(VLOOKUP(F32,Assumptions!$A$16:$C$20,2,FALSE),0.40) | Z32: =IFERROR(VLOOKUP(F32,Assumptions!$A$16:$C$20,3,FALSE),0.30) | AA32: =IF(P32<>"",P32*X32*W32,IF(L32<>"",L32/(1-Y32),K32)) | AB32: =IF(L32<>"",L32/(1-Z32),"") | AC32: =IF(AB32="",AA32,MAX(AA32,AB32)) | AD32: =IF(AC32="","",AC32*G32) | AE32: =IF(AD32="","",ROUNDUP(AD32,0)-0.01) | AF32: =IF(P32<>"","Competitor-based",IF(L32<>"","Cost+margin","Needs review"))
A33: blank-boxes-for-7ml-jars | B33: Blank Boxes for Jars | C33: Oil Slick Blank Boxes for Jars are clean, retail-ready outer boxes for your concentrate jars, built for brands and extractors who want pro packaging without being locked into pre-printed designs. Sized to fit 5ml, 6ml, 7… | D33: Size: 6ml / Quantity: 5000 / Color: Black | E33: BOX FOR JAR 6ML 5000 | F33: Packaging | G33: 5000 | H33: pcs | I33: 12.99 | K33: =IFERROR(I33/G33,"") | L33: =IFERROR(J33/G33,"") | M33: =IFERROR((I33-J33)/I33,"") | P33: =IFERROR(N33/O33,"") | S33: =IFERROR(Q33/R33,"") | W33: =IF(G33="","",IF(G33<=Assumptions!$B$9,Assumptions!$C$9,IF(G33<=Assumptions!$B$10,Assumptions!$C$10,IF(G33<=Assumptions!$B$11,Assumptions!$C$11,Assumptions!$C$12)))) | X33: =IF(F33="Branded",Assumptions!$B$5,IF(OR(F33="Packaging",F33="Bags"),Assumptions!$B$4,1)) | Y33: =IFERROR(VLOOKUP(F33,Assumptions!$A$16:$C$20,2,FALSE),0.40) | Z33: =IFERROR(VLOOKUP(F33,Assumptions!$A$16:$C$20,3,FALSE),0.30) | AA33: =IF(P33<>"",P33*X33*W33,IF(L33<>"",L33/(1-Y33),K33)) | AB33: =IF(L33<>"",L33/(1-Z33),"") | AC33: =IF(AB33="",AA33,MAX(AA33,AB33)) | AD33: =IF(AC33="","",AC33*G33) | AE33: =IF(AD33="","",ROUNDUP(AD33,0)-0.01) | AF33: =IF(P33<>"","Competitor-based",IF(L33<>"","Cost+margin","Needs review"))
A34: blank-boxes-for-7ml-jars | B34: Blank Boxes for Jars | C34: Oil Slick Blank Boxes for Jars are clean, retail-ready outer boxes for your concentrate jars, built for brands and extractors who want pro packaging without being locked into pre-printed designs. Sized to fit 5ml, 6ml, 7… | D34: Size: 7ml / Quantity: 5000 / Color: Black | E34: BOX FOR JAR 7ML 5000 | F34: Packaging | G34: 5000 | H34: pcs | I34: 9.99 | K34: =IFERROR(I34/G34,"") | L34: =IFERROR(J34/G34,"") | M34: =IFERROR((I34-J34)/I34,"") | P34: =IFERROR(N34/O34,"") | S34: =IFERROR(Q34/R34,"") | W34: =IF(G34="","",IF(G34<=Assumptions!$B$9,Assumptions!$C$9,IF(G34<=Assumptions!$B$10,Assumptions!$C$10,IF(G34<=Assumptions!$B$11,Assumptions!$C$11,Assumptions!$C$12)))) | X34: =IF(F34="Branded",Assumptions!$B$5,IF(OR(F34="Packaging",F34="Bags"),Assumptions!$B$4,1)) | Y34: =IFERROR(VLOOKUP(F34,Assumptions!$A$16:$C$20,2,FALSE),0.40) | Z34: =IFERROR(VLOOKUP(F34,Assumptions!$A$16:$C$20,3,FALSE),0.30) | AA34: =IF(P34<>"",P34*X34*W34,IF(L34<>"",L34/(1-Y34),K34)) | AB34: =IF(L34<>"",L34/(1-Z34),"") | AC34: =IF(AB34="",AA34,MAX(AA34,AB34)) | AD34: =IF(AC34="","",AC34*G34) | AE34: =IF(AD34="","",ROUNDUP(AD34,0)-0.01) | AF34: =IF(P34<>"","Competitor-based",IF(L34<>"","Cost+margin","Needs review"))
A35: blank-boxes-for-7ml-jars | B35: Blank Boxes for Jars | C35: Oil Slick Blank Boxes for Jars are clean, retail-ready outer boxes for your concentrate jars, built for brands and extractors who want pro packaging without being locked into pre-printed designs. Sized to fit 5ml, 6ml, 7… | D35: Size: 7ml / Quantity: 5000 / Color: White | E35: BOX FOR JAR 7ML 5000 | F35: Packaging | G35: 5000 | H35: pcs | I35: 19.99 | K35: =IFERROR(I35/G35,"") | L35: =IFERROR(J35/G35,"") | M35: =IFERROR((I35-J35)/I35,"") | P35: =IFERROR(N35/O35,"") | S35: =IFERROR(Q35/R35,"") | W35: =IF(G35="","",IF(G35<=Assumptions!$B$9,Assumptions!$C$9,IF(G35<=Assumptions!$B$10,Assumptions!$C$10,IF(G35<=Assumptions!$B$11,Assumptions!$C$11,Assumptions!$C$12)))) | X35: =IF(F35="Branded",Assumptions!$B$5,IF(OR(F35="Packaging",F35="Bags"),Assumptions!$B$4,1)) | Y35: =IFERROR(VLOOKUP(F35,Assumptions!$A$16:$C$20,2,FALSE),0.40) | Z35: =IFERROR(VLOOKUP(F35,Assumptions!$A$16:$C$20,3,FALSE),0.30) | AA35: =IF(P35<>"",P35*X35*W35,IF(L35<>"",L35/(1-Y35),K35)) | AB35: =IF(L35<>"",L35/(1-Z35),"") | AC35: =IF(AB35="",AA35,MAX(AA35,AB35)) | AD35: =IF(AC35="","",AC35*G35) | AE35: =IF(AD35="","",ROUNDUP(AD35,0)-0.01) | AF35: =IF(P35<>"","Competitor-based",IF(L35<>"","Cost+margin","Needs review"))
A36: blank-boxes-for-7ml-jars | B36: Blank Boxes for Jars | C36: Oil Slick Blank Boxes for Jars are clean, retail-ready outer boxes for your concentrate jars, built for brands and extractors who want pro packaging without being locked into pre-printed designs. Sized to fit 5ml, 6ml, 7… | D36: Size: 9ml / Quantity: 5000 / Color: Black | E36: BOX FOR JAR 9ML 5000 | F36: Packaging | G36: 5000 | H36: pcs | I36: 14.99 | J36: 2461 | K36: =IFERROR(I36/G36,"") | L36: =IFERROR(J36/G36,"") | M36: =IFERROR((I36-J36)/I36,"") | P36: =IFERROR(N36/O36,"") | S36: =IFERROR(Q36/R36,"") | W36: =IF(G36="","",IF(G36<=Assumptions!$B$9,Assumptions!$C$9,IF(G36<=Assumptions!$B$10,Assumptions!$C$10,IF(G36<=Assumptions!$B$11,Assumptions!$C$11,Assumptions!$C$12)))) | X36: =IF(F36="Branded",Assumptions!$B$5,IF(OR(F36="Packaging",F36="Bags"),Assumptions!$B$4,1)) | Y36: =IFERROR(VLOOKUP(F36,Assumptions!$A$16:$C$20,2,FALSE),0.40) | Z36: =IFERROR(VLOOKUP(F36,Assumptions!$A$16:$C$20,3,FALSE),0.30) | AA36: =IF(P36<>"",P36*X36*W36,IF(L36<>"",L36/(1-Y36),K36)) | AB36: =IF(L36<>"",L36/(1-Z36),"") | AC36: =IF(AB36="",AA36,MAX(AA36,AB36)) | AD36: =IF(AC36="","",AC36*G36) | AE36: =IF(AD36="","",ROUNDUP(AD36,0)-0.01) | AF36: =IF(P36<>"","Competitor-based",IF(L36<>"","Cost+margin","Needs review"))
A37: blank-boxes-for-7ml-jars | B37: Blank Boxes for Jars | C37: Oil Slick Blank Boxes for Jars are clean, retail-ready outer boxes for your concentrate jars, built for brands and extractors who want pro packaging without being locked into pre-printed designs. Sized to fit 5ml, 6ml, 7… | D37: Size: 9ml / Quantity: 5000 / Color: White | E37: BOX FOR JAR 9ML 5000 | F37: Packaging | G37: 5000 | H37: pcs | I37: 9.99 | J37: 2256 | K37: =IFERROR(I37/G37,"") | L37: =IFERROR(J37/G37,"") | M37: =IFERROR((I37-J37)/I37,"") | P37: =IFERROR(N37/O37,"") | S37: =IFERROR(Q37/R37,"") | W37: =IF(G37="","",IF(G37<=Assumptions!$B$9,Assumptions!$C$9,IF(G37<=Assumptions!$B$10,Assumptions!$C$10,IF(G37<=Assumptions!$B$11,Assumptions!$C$11,Assumptions!$C$12)))) | X37: =IF(F37="Branded",Assumptions!$B$5,IF(OR(F37="Packaging",F37="Bags"),Assumptions!$B$4,1)) | Y37: =IFERROR(VLOOKUP(F37,Assumptions!$A$16:$C$20,2,FALSE),0.40) | Z37: =IFERROR(VLOOKUP(F37,Assumptions!$A$16:$C$20,3,FALSE),0.30) | AA37: =IF(P37<>"",P37*X37*W37,IF(L37<>"",L37/(1-Y37),K37)) | AB37: =IF(L37<>"",L37/(1-Z37),"") | AC37: =IF(AB37="",AA37,MAX(AA37,AB37)) | AD37: =IF(AC37="","",AC37*G37) | AE37: =IF(AD37="","",ROUNDUP(AD37,0)-0.01) | AF37: =IF(P37<>"","Competitor-based",IF(L37<>"","Cost+margin","Needs review"))
A38: blank-boxes-for-7ml-jars | B38: Blank Boxes for Jars | C38: Oil Slick Blank Boxes for Jars are clean, retail-ready outer boxes for your concentrate jars, built for brands and extractors who want pro packaging without being locked into pre-printed designs. Sized to fit 5ml, 6ml, 7… | D38: Size: 5ml / Quantity: 10000 / Color: Black | E38: BOX FOR JAR 5ML 10000 | F38: Packaging | G38: 10000 | H38: pcs | I38: 9.99 | K38: =IFERROR(I38/G38,"") | L38: =IFERROR(J38/G38,"") | M38: =IFERROR((I38-J38)/I38,"") | P38: =IFERROR(N38/O38,"") | S38: =IFERROR(Q38/R38,"") | W38: =IF(G38="","",IF(G38<=Assumptions!$B$9,Assumptions!$C$9,IF(G38<=Assumptions!$B$10,Assumptions!$C$10,IF(G38<=Assumptions!$B$11,Assumptions!$C$11,Assumptions!$C$12)))) | X38: =IF(F38="Branded",Assumptions!$B$5,IF(OR(F38="Packaging",F38="Bags"),Assumptions!$B$4,1)) | Y38: =IFERROR(VLOOKUP(F38,Assumptions!$A$16:$C$20,2,FALSE),0.40) | Z38: =IFERROR(VLOOKUP(F38,Assumptions!$A$16:$C$20,3,FALSE),0.30) | AA38: =IF(P38<>"",P38*X38*W38,IF(L38<>"",L38/(1-Y38),K38)) | AB38: =IF(L38<>"",L38/(1-Z38),"") | AC38: =IF(AB38="",AA38,MAX(AA38,AB38)) | AD38: =IF(AC38="","",AC38*G38) | AE38: =IF(AD38="","",ROUNDUP(AD38,0)-0.01) | AF38: =IF(P38<>"","Competitor-based",IF(L38<>"","Cost+margin","Needs review"))
A39: blank-boxes-for-7ml-jars | B39: Blank Boxes for Jars | C39: Oil Slick Blank Boxes for Jars are clean, retail-ready outer boxes for your concentrate jars, built for brands and extractors who want pro packaging without being locked into pre-printed designs. Sized to fit 5ml, 6ml, 7… | D39: Size: 5ml / Quantity: 10000 / Color: White | E39: BOX FOR JAR 5ML 10000 | F39: Packaging | G39: 10000 | H39: pcs | I39: 10.99 | K39: =IFERROR(I39/G39,"") | L39: =IFERROR(J39/G39,"") | M39: =IFERROR((I39-J39)/I39,"") | P39: =IFERROR(N39/O39,"") | S39: =IFERROR(Q39/R39,"") | W39: =IF(G39="","",IF(G39<=Assumptions!$B$9,Assumptions!$C$9,IF(G39<=Assumptions!$B$10,Assumptions!$C$10,IF(G39<=Assumptions!$B$11,Assumptions!$C$11,Assumptions!$C$12)))) | X39: =IF(F39="Branded",Assumptions!$B$5,IF(OR(F39="Packaging",F39="Bags"),Assumptions!$B$4,1)) | Y39: =IFERROR(VLOOKUP(F39,Assumptions!$A$16:$C$20,2,FALSE),0.40) | Z39: =IFERROR(VLOOKUP(F39,Assumptions!$A$16:$C$20,3,FALSE),0.30) | AA39: =IF(P39<>"",P39*X39*W39,IF(L39<>"",L39/(1-Y39),K39)) | AB39: =IF(L39<>"",L39/(1-Z39),"") | AC39: =IF(AB39="",AA39,MAX(AA39,AB39)) | AD39: =IF(AC39="","",AC39*G39) | AE39: =IF(AD39="","",ROUNDUP(AD39,0)-0.01) | AF39: =IF(P39<>"","Competitor-based",IF(L39<>"","Cost+margin","Needs review"))
A40: blank-boxes-for-7ml-jars | B40: Blank Boxes for Jars | C40: Oil Slick Blank Boxes for Jars are clean, retail-ready outer boxes for your concentrate jars, built for brands and extractors who want pro packaging without being locked into pre-printed designs. Sized to fit 5ml, 6ml, 7… | D40: Size: 6ml / Quantity: 10000 / Color: White | E40: BOX FOR JAR 6ML 10000 | F40: Packaging | G40: 10000 | H40: pcs | I40: 29.99 | K40: =IFERROR(I40/G40,"") | L40: =IFERROR(J40/G40,"") | M40: =IFERROR((I40-J40)/I40,"") | P40: =IFERROR(N40/O40,"") | S40: =IFERROR(Q40/R40,"") | W40: =IF(G40="","",IF(G40<=Assumptions!$B$9,Assumptions!$C$9,IF(G40<=Assumptions!$B$10,Assumptions!$C$10,IF(G40<=Assumptions!$B$11,Assumptions!$C$11,Assumptions!$C$12)))) | X40: =IF(F40="Branded",Assumptions!$B$5,IF(OR(F40="Packaging",F40="Bags"),Assumptions!$B$4,1)) | Y40: =IFERROR(VLOOKUP(F40,Assumptions!$A$16:$C$20,2,FALSE),0.40) | Z40: =IFERROR(VLOOKUP(F40,Assumptions!$A$16:$C$20,3,FALSE),0.30) | AA40: =IF(P40<>"",P40*X40*W40,IF(L40<>"",L40/(1-Y40),K40)) | AB40: =IF(L40<>"",L40/(1-Z40),"") | AC40: =IF(AB40="",AA40,MAX(AA40,AB40)) | AD40: =IF(AC40="","",AC40*G40) | AE40: =IF(AD40="","",ROUNDUP(AD40,0)-0.01) | AF40: =IF(P40<>"","Competitor-based",IF(L40<>"","Cost+margin","Needs review"))
A41: blank-boxes-for-7ml-jars | B41: Blank Boxes for Jars | C41: Oil Slick Blank Boxes for Jars are clean, retail-ready outer boxes for your concentrate jars, built for brands and extractors who want pro packaging without being locked into pre-printed designs. Sized to fit 5ml, 6ml, 7… | D41: Size: 9ml / Quantity: 1000 / Color: White | E41: BOX FOR JAR 9ML 1000 | F41: Packaging | G41: 1000 | H41: pcs | I41: 19.99 | J41: 570 | K41: =IFERROR(I41/G41,"") | L41: =IFERROR(J41/G41,"") | M41: =IFERROR((I41-J41)/I41,"") | P41: =IFERROR(N41/O41,"") | S41: =IFERROR(Q41/R41,"") | W41: =IF(G41="","",IF(G41<=Assumptions!$B$9,Assumptions!$C$9,IF(G41<=Assumptions!$B$10,Assumptions!$C$10,IF(G41<=Assumptions!$B$11,Assumptions!$C$11,Assumptions!$C$12)))) | X41: =IF(F41="Branded",Assumptions!$B$5,IF(OR(F41="Packaging",F41="Bags"),Assumptions!$B$4,1)) | Y41: =IFERROR(VLOOKUP(F41,Assumptions!$A$16:$C$20,2,FALSE),0.40) | Z41: =IFERROR(VLOOKUP(F41,Assumptions!$A$16:$C$20,3,FALSE),0.30) | AA41: =IF(P41<>"",P41*X41*W41,IF(L41<>"",L41/(1-Y41),K41)) | AB41: =IF(L41<>"",L41/(1-Z41),"") | AC41: =IF(AB41="",AA41,MAX(AA41,AB41)) | AD41: =IF(AC41="","",AC41*G41) | AE41: =IF(AD41="","",ROUNDUP(AD41,0)-0.01) | AF41: =IF(P41<>"","Competitor-based",IF(L41<>"","Cost+margin","Needs review"))
...
